2023-12-24 23:54:59,370 - ERROR - Exception on /api/users/permission/mds.tanbin@live.com [OPTIONS]
Traceback (most recent call last):
  File "C:\Users\Tanbin\AppData\Local\Programs\Python\Python311\Lib\site-packages\flask\app.py", line 1484, in full_dispatch_request
    rv = self.dispatch_request()
         ^^^^^^^^^^^^^^^^^^^^^^^
  File "C:\Users\Tanbin\AppData\Local\Programs\Python\Python311\Lib\site-packages\flask\app.py", line 1458, in dispatch_request
    self.raise_routing_exception(req)
  File "C:\Users\Tanbin\AppData\Local\Programs\Python\Python311\Lib\site-packages\flask\app.py", line 1440, in raise_routing_exception
    raise request.routing_exception  # type: ignore
    ^^^^^^^^^^^^^^^^^^^^^^^^^^^^^^^
  File "C:\Users\Tanbin\AppData\Local\Programs\Python\Python311\Lib\site-packages\flask\ctx.py", line 353, in match_request
    result = self.url_adapter.match(return_rule=True)  # type: ignore
             ^^^^^^^^^^^^^^^^^^^^^^^^^^^^^^^^^^^^^^^^
  File "C:\Users\Tanbin\AppData\Local\Programs\Python\Python311\Lib\site-packages\werkzeug\routing\map.py", line 655, in match
    raise NotFound() from None
werkzeug.exceptions.NotFound: 404 Not Found: The requested URL was not found on the server. If you entered the URL manually please check your spelling and try again.

During handling of the above exception, another exception occurred:

Traceback (most recent call last):
  File "C:\Users\Tanbin\AppData\Local\Programs\Python\Python311\Lib\site-packages\flask\app.py", line 2190, in wsgi_app
    response = self.full_dispatch_request()
               ^^^^^^^^^^^^^^^^^^^^^^^^^^^^
  File "C:\Users\Tanbin\AppData\Local\Programs\Python\Python311\Lib\site-packages\flask\app.py", line 1486, in full_dispatch_request
    rv = self.handle_user_exception(e)
         ^^^^^^^^^^^^^^^^^^^^^^^^^^^^^
  File "C:\Users\Tanbin\AppData\Local\Programs\Python\Python311\Lib\site-packages\flask_cors\extension.py", line 176, in wrapped_function
    return cors_after_request(app.make_response(f(*args, **kwargs)))
                                                ^^^^^^^^^^^^^^^^^^
  File "C:\Users\Tanbin\AppData\Local\Programs\Python\Python311\Lib\site-packages\flask\app.py", line 1341, in handle_user_exception
    return self.handle_http_exception(e)
           ^^^^^^^^^^^^^^^^^^^^^^^^^^^^^
  File "C:\Users\Tanbin\AppData\Local\Programs\Python\Python311\Lib\site-packages\flask\app.py", line 1281, in handle_http_exception
    return self.ensure_sync(handler)(e)
           ^^^^^^^^^^^^^^^^^^^^^^^^^^^^
TypeError: page_not_found() takes 0 positional arguments but 1 was given
2023-12-24 23:54:59,375 - INFO - 192.168.0.133 - - [24/Dec/2023 23:54:59] "[35m[1mOPTIONS /api/users/permission/mds.tanbin@live.com HTTP/1.1[0m" 500 -
2023-12-24 23:54:59,375 - ERROR - Exception on /api/users/permission/mds.tanbin@live.com [OPTIONS]
Traceback (most recent call last):
  File "C:\Users\Tanbin\AppData\Local\Programs\Python\Python311\Lib\site-packages\flask\app.py", line 1484, in full_dispatch_request
    rv = self.dispatch_request()
         ^^^^^^^^^^^^^^^^^^^^^^^
  File "C:\Users\Tanbin\AppData\Local\Programs\Python\Python311\Lib\site-packages\flask\app.py", line 1458, in dispatch_request
    self.raise_routing_exception(req)
  File "C:\Users\Tanbin\AppData\Local\Programs\Python\Python311\Lib\site-packages\flask\app.py", line 1440, in raise_routing_exception
    raise request.routing_exception  # type: ignore
    ^^^^^^^^^^^^^^^^^^^^^^^^^^^^^^^
  File "C:\Users\Tanbin\AppData\Local\Programs\Python\Python311\Lib\site-packages\flask\ctx.py", line 353, in match_request
    result = self.url_adapter.match(return_rule=True)  # type: ignore
             ^^^^^^^^^^^^^^^^^^^^^^^^^^^^^^^^^^^^^^^^
  File "C:\Users\Tanbin\AppData\Local\Programs\Python\Python311\Lib\site-packages\werkzeug\routing\map.py", line 655, in match
    raise NotFound() from None
werkzeug.exceptions.NotFound: 404 Not Found: The requested URL was not found on the server. If you entered the URL manually please check your spelling and try again.

During handling of the above exception, another exception occurred:

Traceback (most recent call last):
  File "C:\Users\Tanbin\AppData\Local\Programs\Python\Python311\Lib\site-packages\flask\app.py", line 2190, in wsgi_app
    response = self.full_dispatch_request()
               ^^^^^^^^^^^^^^^^^^^^^^^^^^^^
  File "C:\Users\Tanbin\AppData\Local\Programs\Python\Python311\Lib\site-packages\flask\app.py", line 1486, in full_dispatch_request
    rv = self.handle_user_exception(e)
         ^^^^^^^^^^^^^^^^^^^^^^^^^^^^^
  File "C:\Users\Tanbin\AppData\Local\Programs\Python\Python311\Lib\site-packages\flask_cors\extension.py", line 176, in wrapped_function
    return cors_after_request(app.make_response(f(*args, **kwargs)))
                                                ^^^^^^^^^^^^^^^^^^
  File "C:\Users\Tanbin\AppData\Local\Programs\Python\Python311\Lib\site-packages\flask\app.py", line 1341, in handle_user_exception
    return self.handle_http_exception(e)
           ^^^^^^^^^^^^^^^^^^^^^^^^^^^^^
  File "C:\Users\Tanbin\AppData\Local\Programs\Python\Python311\Lib\site-packages\flask\app.py", line 1281, in handle_http_exception
    return self.ensure_sync(handler)(e)
           ^^^^^^^^^^^^^^^^^^^^^^^^^^^^
TypeError: page_not_found() takes 0 positional arguments but 1 was given
2023-12-24 23:54:59,379 - INFO - 192.168.0.133 - - [24/Dec/2023 23:54:59] "[35m[1mOPTIONS /api/users/permission/mds.tanbin@live.com HTTP/1.1[0m" 500 -
2023-12-24 23:56:34,337 - ERROR - Exception on /api/users/permission/mds.tanbin@live.com [OPTIONS]
Traceback (most recent call last):
  File "C:\Users\Tanbin\AppData\Local\Programs\Python\Python311\Lib\site-packages\flask\app.py", line 1484, in full_dispatch_request
    rv = self.dispatch_request()
         ^^^^^^^^^^^^^^^^^^^^^^^
  File "C:\Users\Tanbin\AppData\Local\Programs\Python\Python311\Lib\site-packages\flask\app.py", line 1458, in dispatch_request
    self.raise_routing_exception(req)
  File "C:\Users\Tanbin\AppData\Local\Programs\Python\Python311\Lib\site-packages\flask\app.py", line 1440, in raise_routing_exception
    raise request.routing_exception  # type: ignore
    ^^^^^^^^^^^^^^^^^^^^^^^^^^^^^^^
  File "C:\Users\Tanbin\AppData\Local\Programs\Python\Python311\Lib\site-packages\flask\ctx.py", line 353, in match_request
    result = self.url_adapter.match(return_rule=True)  # type: ignore
             ^^^^^^^^^^^^^^^^^^^^^^^^^^^^^^^^^^^^^^^^
  File "C:\Users\Tanbin\AppData\Local\Programs\Python\Python311\Lib\site-packages\werkzeug\routing\map.py", line 655, in match
    raise NotFound() from None
werkzeug.exceptions.NotFound: 404 Not Found: The requested URL was not found on the server. If you entered the URL manually please check your spelling and try again.

During handling of the above exception, another exception occurred:

Traceback (most recent call last):
  File "C:\Users\Tanbin\AppData\Local\Programs\Python\Python311\Lib\site-packages\flask\app.py", line 2190, in wsgi_app
    response = self.full_dispatch_request()
               ^^^^^^^^^^^^^^^^^^^^^^^^^^^^
  File "C:\Users\Tanbin\AppData\Local\Programs\Python\Python311\Lib\site-packages\flask\app.py", line 1486, in full_dispatch_request
    rv = self.handle_user_exception(e)
         ^^^^^^^^^^^^^^^^^^^^^^^^^^^^^
  File "C:\Users\Tanbin\AppData\Local\Programs\Python\Python311\Lib\site-packages\flask_cors\extension.py", line 176, in wrapped_function
    return cors_after_request(app.make_response(f(*args, **kwargs)))
                                                ^^^^^^^^^^^^^^^^^^
  File "C:\Users\Tanbin\AppData\Local\Programs\Python\Python311\Lib\site-packages\flask\app.py", line 1341, in handle_user_exception
    return self.handle_http_exception(e)
           ^^^^^^^^^^^^^^^^^^^^^^^^^^^^^
  File "C:\Users\Tanbin\AppData\Local\Programs\Python\Python311\Lib\site-packages\flask\app.py", line 1281, in handle_http_exception
    return self.ensure_sync(handler)(e)
           ^^^^^^^^^^^^^^^^^^^^^^^^^^^^
TypeError: page_not_found() takes 0 positional arguments but 1 was given
2023-12-24 23:56:34,342 - INFO - 192.168.0.133 - - [24/Dec/2023 23:56:34] "[35m[1mOPTIONS /api/users/permission/mds.tanbin@live.com HTTP/1.1[0m" 500 -
2023-12-24 23:56:41,842 - ERROR - Exception on /api/users/permission/mds.tanbin@live.com [OPTIONS]
Traceback (most recent call last):
  File "C:\Users\Tanbin\AppData\Local\Programs\Python\Python311\Lib\site-packages\flask\app.py", line 1484, in full_dispatch_request
    rv = self.dispatch_request()
         ^^^^^^^^^^^^^^^^^^^^^^^
  File "C:\Users\Tanbin\AppData\Local\Programs\Python\Python311\Lib\site-packages\flask\app.py", line 1458, in dispatch_request
    self.raise_routing_exception(req)
  File "C:\Users\Tanbin\AppData\Local\Programs\Python\Python311\Lib\site-packages\flask\app.py", line 1440, in raise_routing_exception
    raise request.routing_exception  # type: ignore
    ^^^^^^^^^^^^^^^^^^^^^^^^^^^^^^^
  File "C:\Users\Tanbin\AppData\Local\Programs\Python\Python311\Lib\site-packages\flask\ctx.py", line 353, in match_request
    result = self.url_adapter.match(return_rule=True)  # type: ignore
             ^^^^^^^^^^^^^^^^^^^^^^^^^^^^^^^^^^^^^^^^
  File "C:\Users\Tanbin\AppData\Local\Programs\Python\Python311\Lib\site-packages\werkzeug\routing\map.py", line 655, in match
    raise NotFound() from None
werkzeug.exceptions.NotFound: 404 Not Found: The requested URL was not found on the server. If you entered the URL manually please check your spelling and try again.

During handling of the above exception, another exception occurred:

Traceback (most recent call last):
  File "C:\Users\Tanbin\AppData\Local\Programs\Python\Python311\Lib\site-packages\flask\app.py", line 2190, in wsgi_app
    response = self.full_dispatch_request()
               ^^^^^^^^^^^^^^^^^^^^^^^^^^^^
  File "C:\Users\Tanbin\AppData\Local\Programs\Python\Python311\Lib\site-packages\flask\app.py", line 1486, in full_dispatch_request
    rv = self.handle_user_exception(e)
         ^^^^^^^^^^^^^^^^^^^^^^^^^^^^^
  File "C:\Users\Tanbin\AppData\Local\Programs\Python\Python311\Lib\site-packages\flask_cors\extension.py", line 176, in wrapped_function
    return cors_after_request(app.make_response(f(*args, **kwargs)))
                                                ^^^^^^^^^^^^^^^^^^
  File "C:\Users\Tanbin\AppData\Local\Programs\Python\Python311\Lib\site-packages\flask\app.py", line 1341, in handle_user_exception
    return self.handle_http_exception(e)
           ^^^^^^^^^^^^^^^^^^^^^^^^^^^^^
  File "C:\Users\Tanbin\AppData\Local\Programs\Python\Python311\Lib\site-packages\flask\app.py", line 1281, in handle_http_exception
    return self.ensure_sync(handler)(e)
           ^^^^^^^^^^^^^^^^^^^^^^^^^^^^
TypeError: page_not_found() takes 0 positional arguments but 1 was given
2023-12-24 23:56:41,848 - INFO - 192.168.0.133 - - [24/Dec/2023 23:56:41] "[35m[1mOPTIONS /api/users/permission/mds.tanbin@live.com HTTP/1.1[0m" 500 -
2023-12-24 23:56:47,195 - INFO - 192.168.0.133 - - [24/Dec/2023 23:56:47] "OPTIONS /api/users/pendingList HTTP/1.1" 200 -
2023-12-24 23:56:47,196 - INFO - 192.168.0.133 - - [24/Dec/2023 23:56:47] "OPTIONS /api/users/pendingList HTTP/1.1" 200 -
2023-12-24 23:56:47,202 - INFO - 192.168.0.133 - - [24/Dec/2023 23:56:47] "GET /api/users/pendingList HTTP/1.1" 200 -
2023-12-24 23:56:47,207 - INFO - 192.168.0.133 - - [24/Dec/2023 23:56:47] "GET /api/users/pendingList HTTP/1.1" 200 -
2023-12-24 23:56:50,492 - ERROR - Exception on /api/users/permission/mds.tanbin@live.com [OPTIONS]
Traceback (most recent call last):
  File "C:\Users\Tanbin\AppData\Local\Programs\Python\Python311\Lib\site-packages\flask\app.py", line 1484, in full_dispatch_request
    rv = self.dispatch_request()
         ^^^^^^^^^^^^^^^^^^^^^^^
  File "C:\Users\Tanbin\AppData\Local\Programs\Python\Python311\Lib\site-packages\flask\app.py", line 1458, in dispatch_request
    self.raise_routing_exception(req)
  File "C:\Users\Tanbin\AppData\Local\Programs\Python\Python311\Lib\site-packages\flask\app.py", line 1440, in raise_routing_exception
    raise request.routing_exception  # type: ignore
    ^^^^^^^^^^^^^^^^^^^^^^^^^^^^^^^
  File "C:\Users\Tanbin\AppData\Local\Programs\Python\Python311\Lib\site-packages\flask\ctx.py", line 353, in match_request
    result = self.url_adapter.match(return_rule=True)  # type: ignore
             ^^^^^^^^^^^^^^^^^^^^^^^^^^^^^^^^^^^^^^^^
  File "C:\Users\Tanbin\AppData\Local\Programs\Python\Python311\Lib\site-packages\werkzeug\routing\map.py", line 655, in match
    raise NotFound() from None
werkzeug.exceptions.NotFound: 404 Not Found: The requested URL was not found on the server. If you entered the URL manually please check your spelling and try again.

During handling of the above exception, another exception occurred:

Traceback (most recent call last):
  File "C:\Users\Tanbin\AppData\Local\Programs\Python\Python311\Lib\site-packages\flask\app.py", line 2190, in wsgi_app
    response = self.full_dispatch_request()
               ^^^^^^^^^^^^^^^^^^^^^^^^^^^^
  File "C:\Users\Tanbin\AppData\Local\Programs\Python\Python311\Lib\site-packages\flask\app.py", line 1486, in full_dispatch_request
    rv = self.handle_user_exception(e)
         ^^^^^^^^^^^^^^^^^^^^^^^^^^^^^
  File "C:\Users\Tanbin\AppData\Local\Programs\Python\Python311\Lib\site-packages\flask_cors\extension.py", line 176, in wrapped_function
    return cors_after_request(app.make_response(f(*args, **kwargs)))
                                                ^^^^^^^^^^^^^^^^^^
  File "C:\Users\Tanbin\AppData\Local\Programs\Python\Python311\Lib\site-packages\flask\app.py", line 1341, in handle_user_exception
    return self.handle_http_exception(e)
           ^^^^^^^^^^^^^^^^^^^^^^^^^^^^^
  File "C:\Users\Tanbin\AppData\Local\Programs\Python\Python311\Lib\site-packages\flask\app.py", line 1281, in handle_http_exception
    return self.ensure_sync(handler)(e)
           ^^^^^^^^^^^^^^^^^^^^^^^^^^^^
TypeError: page_not_found() takes 0 positional arguments but 1 was given
2023-12-24 23:56:50,501 - INFO - 192.168.0.133 - - [24/Dec/2023 23:56:50] "[35m[1mOPTIONS /api/users/permission/mds.tanbin@live.com HTTP/1.1[0m" 500 -
2023-12-24 23:56:50,495 - ERROR - Exception on /api/users/permission/mds.tanbin@live.com [OPTIONS]
Traceback (most recent call last):
  File "C:\Users\Tanbin\AppData\Local\Programs\Python\Python311\Lib\site-packages\flask\app.py", line 1484, in full_dispatch_request
    rv = self.dispatch_request()
         ^^^^^^^^^^^^^^^^^^^^^^^
  File "C:\Users\Tanbin\AppData\Local\Programs\Python\Python311\Lib\site-packages\flask\app.py", line 1458, in dispatch_request
    self.raise_routing_exception(req)
  File "C:\Users\Tanbin\AppData\Local\Programs\Python\Python311\Lib\site-packages\flask\app.py", line 1440, in raise_routing_exception
    raise request.routing_exception  # type: ignore
    ^^^^^^^^^^^^^^^^^^^^^^^^^^^^^^^
  File "C:\Users\Tanbin\AppData\Local\Programs\Python\Python311\Lib\site-packages\flask\ctx.py", line 353, in match_request
    result = self.url_adapter.match(return_rule=True)  # type: ignore
             ^^^^^^^^^^^^^^^^^^^^^^^^^^^^^^^^^^^^^^^^
  File "C:\Users\Tanbin\AppData\Local\Programs\Python\Python311\Lib\site-packages\werkzeug\routing\map.py", line 655, in match
    raise NotFound() from None
werkzeug.exceptions.NotFound: 404 Not Found: The requested URL was not found on the server. If you entered the URL manually please check your spelling and try again.

During handling of the above exception, another exception occurred:

Traceback (most recent call last):
  File "C:\Users\Tanbin\AppData\Local\Programs\Python\Python311\Lib\site-packages\flask\app.py", line 2190, in wsgi_app
    response = self.full_dispatch_request()
               ^^^^^^^^^^^^^^^^^^^^^^^^^^^^
  File "C:\Users\Tanbin\AppData\Local\Programs\Python\Python311\Lib\site-packages\flask\app.py", line 1486, in full_dispatch_request
    rv = self.handle_user_exception(e)
         ^^^^^^^^^^^^^^^^^^^^^^^^^^^^^
  File "C:\Users\Tanbin\AppData\Local\Programs\Python\Python311\Lib\site-packages\flask_cors\extension.py", line 176, in wrapped_function
    return cors_after_request(app.make_response(f(*args, **kwargs)))
                                                ^^^^^^^^^^^^^^^^^^
  File "C:\Users\Tanbin\AppData\Local\Programs\Python\Python311\Lib\site-packages\flask\app.py", line 1341, in handle_user_exception
    return self.handle_http_exception(e)
           ^^^^^^^^^^^^^^^^^^^^^^^^^^^^^
  File "C:\Users\Tanbin\AppData\Local\Programs\Python\Python311\Lib\site-packages\flask\app.py", line 1281, in handle_http_exception
    return self.ensure_sync(handler)(e)
           ^^^^^^^^^^^^^^^^^^^^^^^^^^^^
TypeError: page_not_found() takes 0 positional arguments but 1 was given
2023-12-24 23:56:50,507 - INFO - 192.168.0.133 - - [24/Dec/2023 23:56:50] "[35m[1mOPTIONS /api/users/permission/mds.tanbin@live.com HTTP/1.1[0m" 500 -
2023-12-24 23:57:42,584 - INFO - [31m[1mWARNING: This is a development server. Do not use it in a production deployment. Use a production WSGI server instead.[0m
 * Running on all addresses (0.0.0.0)
 * Running on http://127.0.0.1:4000
 * Running on http://192.168.0.133:4000
2023-12-24 23:57:42,585 - INFO - [33mPress CTRL+C to quit[0m
2023-12-24 23:57:46,192 - INFO - 192.168.0.133 - - [24/Dec/2023 23:57:46] "OPTIONS /api/users/permission/mds.tanbin@live.com HTTP/1.1" 200 -
2023-12-24 23:57:46,194 - INFO - 192.168.0.133 - - [24/Dec/2023 23:57:46] "OPTIONS /api/users/permission/mds.tanbin@live.com HTTP/1.1" 200 -
2023-12-24 23:57:46,197 - INFO - 192.168.0.133 - - [24/Dec/2023 23:57:46] "[35m[1mGET /api/users/permission/mds.tanbin@live.com HTTP/1.1[0m" 500 -
2023-12-24 23:57:46,202 - INFO - 192.168.0.133 - - [24/Dec/2023 23:57:46] "[35m[1mGET /api/users/permission/mds.tanbin@live.com HTTP/1.1[0m" 500 -
2023-12-24 23:58:10,324 - INFO - 192.168.0.133 - - [24/Dec/2023 23:58:10] "OPTIONS /api/users/permission/mds.tanbin@live.com HTTP/1.1" 200 -
2023-12-24 23:58:10,327 - INFO - 192.168.0.133 - - [24/Dec/2023 23:58:10] "[35m[1mGET /api/users/permission/mds.tanbin@live.com HTTP/1.1[0m" 500 -
2023-12-24 23:58:13,603 - INFO - 192.168.0.133 - - [24/Dec/2023 23:58:13] "[35m[1mGET /api/users/permission/mds.tanbin@live.com HTTP/1.1[0m" 500 -
2023-12-24 23:58:13,608 - INFO - 192.168.0.133 - - [24/Dec/2023 23:58:13] "[35m[1mGET /api/users/permission/mds.tanbin@live.com HTTP/1.1[0m" 500 -
2023-12-24 23:58:46,167 - INFO - [31m[1mWARNING: This is a development server. Do not use it in a production deployment. Use a production WSGI server instead.[0m
 * Running on all addresses (0.0.0.0)
 * Running on http://127.0.0.1:4000
 * Running on http://192.168.0.133:4000
2023-12-24 23:58:46,167 - INFO - [33mPress CTRL+C to quit[0m
2023-12-24 23:58:49,812 - INFO - 192.168.0.133 - - [24/Dec/2023 23:58:49] "OPTIONS /api/users/permission/mds.tanbin@live.com HTTP/1.1" 200 -
2023-12-24 23:58:49,813 - INFO - 192.168.0.133 - - [24/Dec/2023 23:58:49] "OPTIONS /api/users/permission/mds.tanbin@live.com HTTP/1.1" 200 -
2023-12-24 23:58:49,818 - INFO - 192.168.0.133 - - [24/Dec/2023 23:58:49] "[35m[1mGET /api/users/permission/mds.tanbin@live.com HTTP/1.1[0m" 500 -
2023-12-24 23:58:49,823 - INFO - 192.168.0.133 - - [24/Dec/2023 23:58:49] "[35m[1mGET /api/users/permission/mds.tanbin@live.com HTTP/1.1[0m" 500 -
